Workbook

Sheet Overview
A1: Power BI Corporate Training: 3-Tier Programme Tracker
A2: Tier 1 Consumers | Tier 2 Creators | Tier 3 Builders. Each session is a 2-hour block, so the content can be delivered on any calendar pattern.
A4: Programme progress by tier
A5: Tier | B5: Audience | C5: Sessions | D5: Planned Hrs | E5: Completed | F5: % Complete | G5: Actual Hrs | H5: Start Date | I5: Last Session
A6: Tier 1: Report Consumers | B6: Managers, executives and business users who read and act on dashboards | C6: =COUNT('Tier 1 Consumers'!$A$5:$A$8) -> 4 | D6: =SUM('Tier 1 Consumers'!$I$5:$I$8) -> 8 | E6: =COUNTIF('Tier 1 Consumers'!$J$5:$J$8,"Completed") -> 0 | F6: =IF(C6=0,0,E6/C6) -> 0 | G6: =SUM('Tier 1 Consumers'!$K$5:$K$8) -> 0 | H6: ='Schedule Planner'!$B$5 -> 46286 | I6: =IF(MAX('Tier 1 Consumers'!$C$5:$C$8)=0,"",MAX('Tier 1 Consumers'!$C$5:$C$8)) -> 46289
A7: Tier 2: Report Creators | B7: Business, finance and MIS analysts who build reports from existing or simple datasets | C7: =COUNT('Tier 2 Creators'!$A$5:$A$16) -> 12 | D7: =SUM('Tier 2 Creators'!$I$5:$I$16) -> 24 | E7: =COUNTIF('Tier 2 Creators'!$J$5:$J$16,"Completed") -> 0 | F7: =IF(C7=0,0,E7/C7) -> 0 | G7: =SUM('Tier 2 Creators'!$K$5:$K$16) -> 0 | H7: ='Schedule Planner'!$B$15 -> 46286 | I7: =IF(MAX('Tier 2 Creators'!$C$5:$C$16)=0,"",MAX('Tier 2 Creators'!$C$5:$C$16)) -> 46301
A8: Tier 3: Data & Model Builders | B8: BI developers and reporting analysts who own and maintain datasets (PL-300 equivalent) | C8: =COUNT('Tier 3 Builders'!$A$5:$A$34) -> 30 | D8: =SUM('Tier 3 Builders'!$I$5:$I$34) -> 60 | E8: =COUNTIF('Tier 3 Builders'!$J$5:$J$34,"Completed") -> 0 | F8: =IF(C8=0,0,E8/C8) -> 0 | G8: =SUM('Tier 3 Builders'!$K$5:$K$34) -> 0 | H8: ='Schedule Planner'!$B$25 -> 46286 | I8: =IF(MAX('Tier 3 Builders'!$C$5:$C$34)=0,"",MAX('Tier 3 Builders'!$C$5:$C$34)) -> 46325
A10: Progress by module
A11: Tier | B11: Module | C11: Sessions | D11: Completed | E11: % Complete | F11: Planned Hrs | G11: Actual Hrs
A12: Tier 1: Report Consumers | B12: 1. Power BI Foundations | C12: =COUNTIF('Tier 1 Consumers'!$E$5:$E$8,B12) -> 1 | D12: =COUNTIFS('Tier 1 Consumers'!$E$5:$E$8,B12,'Tier 1 Consumers'!$J$5:$J$8,"Completed") -> 0 | E12: =IF(C12=0,0,D12/C12) -> 0 | F12: =SUMIF('Tier 1 Consumers'!$E$5:$E$8,B12,'Tier 1 Consumers'!$I$5:$I$8) -> 2 | G12: =SUMIF('Tier 1 Consumers'!$E$5:$E$8,B12,'Tier 1 Consumers'!$K$5:$K$8) -> 0
A13: Tier 1: Report Consumers | B13: 2. Explore & Interact with Reports | C13: =COUNTIF('Tier 1 Consumers'!$E$5:$E$8,B13) -> 2 | D13: =COUNTIFS('Tier 1 Consumers'!$E$5:$E$8,B13,'Tier 1 Consumers'!$J$5:$J$8,"Completed") -> 0 | E13: =IF(C13=0,0,D13/C13) -> 0 | F13: =SUMIF('Tier 1 Consumers'!$E$5:$E$8,B13,'Tier 1 Consumers'!$I$5:$I$8) -> 4 | G13: =SUMIF('Tier 1 Consumers'!$E$5:$E$8,B13,'Tier 1 Consumers'!$K$5:$K$8) -> 0
A14: Tier 1: Report Consumers | B14: 3. Share & Stay Informed | C14: =COUNTIF('Tier 1 Consumers'!$E$5:$E$8,B14) -> 1 | D14: =COUNTIFS('Tier 1 Consumers'!$E$5:$E$8,B14,'Tier 1 Consumers'!$J$5:$J$8,"Completed") -> 0 | E14: =IF(C14=0,0,D14/C14) -> 0 | F14: =SUMIF('Tier 1 Consumers'!$E$5:$E$8,B14,'Tier 1 Consumers'!$I$5:$I$8) -> 2 | G14: =SUMIF('Tier 1 Consumers'!$E$5:$E$8,B14,'Tier 1 Consumers'!$K$5:$K$8) -> 0
A15: Tier 2: Report Creators | B15: 1. Data Connect & Data Preparation | C15: =COUNTIF('Tier 2 Creators'!$E$5:$E$16,B15) -> 3 | D15: =COUNTIFS('Tier 2 Creators'!$E$5:$E$16,B15,'Tier 2 Creators'!$J$5:$J$16,"Completed") -> 0 | E15: =IF(C15=0,0,D15/C15) -> 0 | F15: =SUMIF('Tier 2 Creators'!$E$5:$E$16,B15,'Tier 2 Creators'!$I$5:$I$16) -> 6 | G15: =SUMIF('Tier 2 Creators'!$E$5:$E$16,B15,'Tier 2 Creators'!$K$5:$K$16) -> 0
A16: Tier 2: Report Creators | B16: 2. Data Model & DAX (Core) | C16: =COUNTIF('Tier 2 Creators'!$E$5:$E$16,B16) -> 4 | D16: =COUNTIFS('Tier 2 Creators'!$E$5:$E$16,B16,'Tier 2 Creators'!$J$5:$J$16,"Completed") -> 0 | E16: =IF(C16=0,0,D16/C16) -> 0 | F16: =SUMIF('Tier 2 Creators'!$E$5:$E$16,B16,'Tier 2 Creators'!$I$5:$I$16) -> 8 | G16: =SUMIF('Tier 2 Creators'!$E$5:$E$16,B16,'Tier 2 Creators'!$K$5:$K$16) -> 0
A17: Tier 2: Report Creators | B17: 3. Visualisations | C17: =COUNTIF('Tier 2 Creators'!$E$5:$E$16,B17) -> 4 | D17: =COUNTIFS('Tier 2 Creators'!$E$5:$E$16,B17,'Tier 2 Creators'!$J$5:$J$16,"Completed") -> 0 | E17: =IF(C17=0,0,D17/C17) -> 0 | F17: =SUMIF('Tier 2 Creators'!$E$5:$E$16,B17,'Tier 2 Creators'!$I$5:$I$16) -> 8 | G17: =SUMIF('Tier 2 Creators'!$E$5:$E$16,B17,'Tier 2 Creators'!$K$5:$K$16) -> 0
A18: Tier 2: Report Creators | B18: 4. Maintenance & Security (Essentials) | C18: =COUNTIF('Tier 2 Creators'!$E$5:$E$16,B18) -> 1 | D18: =COUNTIFS('Tier 2 Creators'!$E$5:$E$16,B18,'Tier 2 Creators'!$J$5:$J$16,"Completed") -> 0 | E18: =IF(C18=0,0,D18/C18) -> 0 | F18: =SUMIF('Tier 2 Creators'!$E$5:$E$16,B18,'Tier 2 Creators'!$I$5:$I$16) -> 2 | G18: =SUMIF('Tier 2 Creators'!$E$5:$E$16,B18,'Tier 2 Creators'!$K$5:$K$16) -> 0
A19: Tier 3: Data & Model Builders | B19: 1. Data Connect & Data Preparation | C19: =COUNTIF('Tier 3 Builders'!$E$5:$E$34,B19) -> 7 | D19: =COUNTIFS('Tier 3 Builders'!$E$5:$E$34,B19,'Tier 3 Builders'!$J$5:$J$34,"Completed") -> 0 | E19: =IF(C19=0,0,D19/C19) -> 0 | F19: =SUMIF('Tier 3 Builders'!$E$5:$E$34,B19,'Tier 3 Builders'!$I$5:$I$34) -> 14 | G19: =SUMIF('Tier 3 Builders'!$E$5:$E$34,B19,'Tier 3 Builders'!$K$5:$K$34) -> 0
A20: Tier 3: Data & Model Builders | B20: 2. Data Model & DAX | C20: =COUNTIF('Tier 3 Builders'!$E$5:$E$34,B20) -> 9 | D20: =COUNTIFS('Tier 3 Builders'!$E$5:$E$34,B20,'Tier 3 Builders'!$J$5:$J$34,"Completed") -> 0 | E20: =IF(C20=0,0,D20/C20) -> 0 | F20: =SUMIF('Tier 3 Builders'!$E$5:$E$34,B20,'Tier 3 Builders'!$I$5:$I$34) -> 18 | G20: =SUMIF('Tier 3 Builders'!$E$5:$E$34,B20,'Tier 3 Builders'!$K$5:$K$34) -> 0
A21: Tier 3: Data & Model Builders | B21: 3. Visualisations | C21: =COUNTIF('Tier 3 Builders'!$E$5:$E$34,B21) -> 7 | D21: =COUNTIFS('Tier 3 Builders'!$E$5:$E$34,B21,'Tier 3 Builders'!$J$5:$J$34,"Completed") -> 0 | E21: =IF(C21=0,0,D21/C21) -> 0 | F21: =SUMIF('Tier 3 Builders'!$E$5:$E$34,B21,'Tier 3 Builders'!$I$5:$I$34) -> 14 | G21: =SUMIF('Tier 3 Builders'!$E$5:$E$34,B21,'Tier 3 Builders'!$K$5:$K$34) -> 0
A22: Tier 3: Data & Model Builders | B22: 4. Maintenance & Security | C22: =COUNTIF('Tier 3 Builders'!$E$5:$E$34,B22) -> 4 | D22: =COUNTIFS('Tier 3 Builders'!$E$5:$E$34,B22,'Tier 3 Builders'!$J$5:$J$34,"Completed") -> 0 | E22: =IF(C22=0,0,D22/C22) -> 0 | F22: =SUMIF('Tier 3 Builders'!$E$5:$E$34,B22,'Tier 3 Builders'!$I$5:$I$34) -> 8 | G22: =SUMIF('Tier 3 Builders'!$E$5:$E$34,B22,'Tier 3 Builders'!$K$5:$K$34) -> 0
A23: Tier 3: Data & Model Builders | B23: 5. Mock Exams & Revision | C23: =COUNTIF('Tier 3 Builders'!$E$5:$E$34,B23) -> 3 | D23: =COUNTIFS('Tier 3 Builders'!$E$5:$E$34,B23,'Tier 3 Builders'!$J$5:$J$34,"Completed") -> 0 | E23: =IF(C23=0,0,D23/C23) -> 0 | F23: =SUMIF('Tier 3 Builders'!$E$5:$E$34,B23,'Tier 3 Builders'!$I$5:$I$34) -> 6 | G23: =SUMIF('Tier 3 Builders'!$E$5:$E$34,B23,'Tier 3 Builders'!$K$5:$K$34) -> 0
A25: How to use this workbook
A26: Yellow cells with blue text are yours to edit: start dates, training days and sessions per day on Schedule Planner; Status, Actual Hrs and Notes on each tier sheet; Date, Score and Max Score on Assessment Log. Everything else calculates.
A27: Scheduling: the content is split into 2-hour sessions with no fixed calendar. On Schedule Planner, pick the start date, the weekdays the client can attend (1 or 0) and sessions per training day. For a Saturday and Sunday client, set Sat and Sun to 1 and use 2 sessions per day.
A28: Set Status to Completed on a tier sheet and this Overview updates completion, hours and module progress automatically.
A29: Pick the tier by role: see Tier Guide for audience, entry level, outcomes and example delivery patterns. The three tiers are independent, so a client can run just one or several.
A30: Planned Hrs is 2 per session (editable on each tier sheet). Public holidays are not excluded from the calculated dates.

Sheet Tier Guide
A1: Tier Guide
A2: Choose the tier by how each employee uses Power BI. Sessions and hours pull from the tier sheets.
A4: Tier | B4: Audience | C4: Entry level | D4: What they can do afterwards | E4: Not covered | F4: Sessions | G4: Total Hrs | H4: Example delivery
A5: Tier 1: Report Consumers | B5: Managers, executives and business users who read and act on dashboards | C5: No Power BI experience needed; basic comfort with Excel helps | D5: Navigate the Power BI Service, read visuals correctly, filter and drill into reports, export, subscribe and set alerts, and follow data-handling rules | E5: Data preparation, data modelling, DAX and building reports | F5: =COUNT('Tier 1 Consumers'!$A$5:$A$8) -> 4 | G5: =SUM('Tier 1 Consumers'!$I$5:$I$8) -> 8 | H5: Two 4-hour training days (2 sessions per day), or 4 short evening sessions
A6: Tier 2: Report Creators | B6: Business, finance and MIS analysts who build reports from existing or simple datasets | C6: Comfortable with Excel formulas and pivot tables; Tier 1 content or equivalent | D6: Load and clean data, build a simple star-schema model, write core DAX measures including time intelligence basics, design interactive reports, publish and share through the Service | E6: Advanced DAX and performance tuning, gateways, incremental refresh, implementing row-level security, deployment pipelines | F6: =COUNT('Tier 2 Creators'!$A$5:$A$16) -> 12 | G6: =SUM('Tier 2 Creators'!$I$5:$I$16) -> 24 | H6: 3 weekends with Saturday and Sunday at 2 sessions per day, or 3 weeks at 4 sessions per week
A7: Tier 3: Data & Model Builders | B7: BI developers and reporting analysts who own and maintain datasets (PL-300 equivalent) | C7: Strong Excel and preferably SQL; Tier 2 skills or equivalent hands-on experience | D7: PL-300-equivalent skills: full data preparation, modelling, advanced DAX, performance tuning, visualisation and AI features, workspace administration, refresh and gateways, row-level and object-level security | E7: Fabric-specific engineering (lakehouses, pipelines) and Power BI admin-portal tenant settings | F7: =COUNT('Tier 3 Builders'!$A$5:$A$34) -> 30 | G7: =SUM('Tier 3 Builders'!$I$5:$I$34) -> 60 | H7: Around 6 weeks at 5 sessions per week, or 8 weekends at 4 sessions per weekend. Sessions 28-30 (mock exams) are optional for clients not seeking certification
A9: Tier 3 module weights follow Microsoft's PL-300 skills measured (roughly 25-30% each for prepare, model and visualise; 15-20% for manage and secure). Check the current study guide, as objectives are updated from time to time.

Sheet Schedule Planner
A1: Schedule Planner
A2: Set the training days for each tier. Session dates on the tier sheets calculate from these inputs. Nothing here assumes weekdays.
K3: Helper calendar: Tier 1: Report Consumers (do not edit) | N3: Helper calendar: Tier 2: Report Creators (do not edit) | Q3: Helper calendar: Tier 3: Data & Model Builders (do not edit)
A4: Tier 1: Report Consumers | K4: Date | L4: Held? | M4: Cumulative | N4: Date | O4: Held? | P4: Cumulative | Q4: Date | R4: Held? | S4: Cumulative
A5: Start date | B5: 46286 | C5: <- placeholder, edit | K5: =$B$5 -> 46286 | L5: =INDEX($B$7:$H$7,WEEKDAY(K5,2)) -> 1 | M5: =SUM(L$5:L5) -> 1 | N5: =$B$15 -> 46286 | O5: =INDEX($B$17:$H$17,WEEKDAY(N5,2)) -> 1 | P5: =SUM(O$5:O5) -> 1 | Q5: =$B$25 -> 46286 | R5: =INDEX($B$27:$H$27,WEEKDAY(Q5,2)) -> 1 | S5: =SUM(R$5:R5) -> 1
A6: Training day | B6: Mon | C6: Tue | D6: Wed | E6: Thu | F6: Fri | G6: Sat | H6: Sun | K6: =K5+1 -> 46287 | L6: =INDEX($B$7:$H$7,WEEKDAY(K6,2)) -> 1 | M6: =SUM(L$5:L6) -> 2 | N6: =N5+1 -> 46287 | O6: =INDEX($B$17:$H$17,WEEKDAY(N6,2)) -> 1 | P6: =SUM(O$5:O6) -> 2 | Q6: =Q5+1 -> 46287 | R6: =INDEX($B$27:$H$27,WEEKDAY(Q6,2)) -> 1 | S6: =SUM(R$5:R6) -> 2
A7: Held on this day? (1 = yes, 0 = no) | B7: 1 | C7: 1 | D7: 1 | E7: 1 | F7: 1 | G7: 0 | H7: 0 | K7: =K6+1 -> 46288 | L7: =INDEX($B$7:$H$7,WEEKDAY(K7,2)) -> 1 | M7: =SUM(L$5:L7) -> 3 | N7: =N6+1 -> 46288 | O7: =INDEX($B$17:$H$17,WEEKDAY(N7,2)) -> 1 | P7: =SUM(O$5:O7) -> 3 | Q7: =Q6+1 -> 46288 | R7: =INDEX($B$27:$H$27,WEEKDAY(Q7,2)) -> 1 | S7: =SUM(R$5:R7) -> 3
A8: Sessions per training day (1 session = 2 hrs) | B8: 1 | K8: =K7+1 -> 46289 | L8: =INDEX($B$7:$H$7,WEEKDAY(K8,2)) -> 1 | M8: =SUM(L$5:L8) -> 4 | N8: =N7+1 -> 46289 | O8: =INDEX($B$17:$H$17,WEEKDAY(N8,2)) -> 1 | P8: =SUM(O$5:O8) -> 4 | Q8: =Q7+1 -> 46289 | R8: =INDEX($B$27:$H$27,WEEKDAY(Q8,2)) -> 1 | S8: =SUM(R$5:R8) -> 4
A9: Total sessions | B9: =COUNT('Tier 1 Consumers'!$A$5:$A$8) -> 4 | K9: =K8+1 -> 46290 | L9: =INDEX($B$7:$H$7,WEEKDAY(K9,2)) -> 1 | M9: =SUM(L$5:L9) -> 5 | N9: =N8+1 -> 46290 | O9: =INDEX($B$17:$H$17,WEEKDAY(N9,2)) -> 1 | P9: =SUM(O$5:O9) -> 5 | Q9: =Q8+1 -> 46290 | R9: =INDEX($B$27:$H$27,WEEKDAY(Q9,2)) -> 1 | S9: =SUM(R$5:R9) -> 5
A10: Training days needed | B10: =IFERROR(ROUNDUP(B9/$B$8,0),"") -> 4 | K10: =K9+1 -> 46291 | L10: =INDEX($B$7:$H$7,WEEKDAY(K10,2)) -> 0 | M10: =SUM(L$5:L10) -> 5 | N10: =N9+1 -> 46291 | O10: =INDEX($B$17:$H$17,WEEKDAY(N10,2)) -> 0 | P10: =SUM(O$5:O10) -> 5 | Q10: =Q9+1 -> 46291 | R10: =INDEX($B$27:$H$27,WEEKDAY(Q10,2)) -> 0 | S10: =SUM(R$5:R10) -> 5
A11: Last session date | B11: =IF(MAX('Tier 1 Consumers'!$C$5:$C$8)=0,"",MAX('Tier 1 Consumers'!$C$5:$C$8)) -> 46289 | K11: =K10+1 -> 46292 | L11: =INDEX($B$7:$H$7,WEEKDAY(K11,2)) -> 0 | M11: =SUM(L$5:L11) -> 5 | N11: =N10+1 -> 46292 | O11: =INDEX($B$17:$H$17,WEEKDAY(N11,2)) -> 0 | P11: =SUM(O$5:O11) -> 5 | Q11: =Q10+1 -> 46292 | R11: =INDEX($B$27:$H$27,WEEKDAY(Q11,2)) -> 0 | S11: =SUM(R$5:R11) -> 5
K12: =K11+1 -> 46293 | L12: =INDEX($B$7:$H$7,WEEKDAY(K12,2)) -> 1 | M12: =SUM(L$5:L12) -> 6 | N12: =N11+1 -> 46293 | O12: =INDEX($B$17:$H$17,WEEKDAY(N12,2)) -> 1 | P12: =SUM(O$5:O12) -> 6 | Q12: =Q11+1 -> 46293 | R12: =INDEX($B$27:$H$27,WEEKDAY(Q12,2)) -> 1 | S12: =SUM(R$5:R12) -> 6
K13: =K12+1 -> 46294 | L13: =INDEX($B$7:$H$7,WEEKDAY(K13,2)) -> 1 | M13: =SUM(L$5:L13) -> 7 | N13: =N12+1 -> 46294 | O13: =INDEX($B$17:$H$17,WEEKDAY(N13,2)) -> 1 | P13: =SUM(O$5:O13) -> 7 | Q13: =Q12+1 -> 46294 | R13: =INDEX($B$27:$H$27,WEEKDAY(Q13,2)) -> 1 | S13: =SUM(R$5:R13) -> 7
A14: Tier 2: Report Creators | K14: =K13+1 -> 46295 | L14: =INDEX($B$7:$H$7,WEEKDAY(K14,2)) -> 1 | M14: =SUM(L$5:L14) -> 8 | N14: =N13+1 -> 46295 | O14: =INDEX($B$17:$H$17,WEEKDAY(N14,2)) -> 1 | P14: =SUM(O$5:O14) -> 8 | Q14: =Q13+1 -> 46295 | R14: =INDEX($B$27:$H$27,WEEKDAY(Q14,2)) -> 1 | S14: =SUM(R$5:R14) -> 8
A15: Start date | B15: 46286 | C15: <- placeholder, edit | K15: =K14+1 -> 46296 | L15: =INDEX($B$7:$H$7,WEEKDAY(K15,2)) -> 1 | M15: =SUM(L$5:L15) -> 9 | N15: =N14+1 -> 46296 | O15: =INDEX($B$17:$H$17,WEEKDAY(N15,2)) -> 1 | P15: =SUM(O$5:O15) -> 9 | Q15: =Q14+1 -> 46296 | R15: =INDEX($B$27:$H$27,WEEKDAY(Q15,2)) -> 1 | S15: =SUM(R$5:R15) -> 9
A16: Training day | B16: Mon | C16: Tue | D16: Wed | E16: Thu | F16: Fri | G16: Sat | H16: Sun | K16: =K15+1 -> 46297 | L16: =INDEX($B$7:$H$7,WEEKDAY(K16,2)) -> 1 | M16: =SUM(L$5:L16) -> 10 | N16: =N15+1 -> 46297 | O16: =INDEX($B$17:$H$17,WEEKDAY(N16,2)) -> 1 | P16: =SUM(O$5:O16) -> 10 | Q16: =Q15+1 -> 46297 | R16: =INDEX($B$27:$H$27,WEEKDAY(Q16,2)) -> 1 | S16: =SUM(R$5:R16) -> 10
A17: Held on this day? (1 = yes, 0 = no) | B17: 1 | C17: 1 | D17: 1 | E17: 1 | F17: 1 | G17: 0 | H17: 0 | K17: =K16+1 -> 46298 | L17: =INDEX($B$7:$H$7,WEEKDAY(K17,2)) -> 0 | M17: =SUM(L$5:L17) -> 10 | N17: =N16+1 -> 46298 | O17: =INDEX($B$17:$H$17,WEEKDAY(N17,2)) -> 0 | P17: =SUM(O$5:O17) -> 10 | Q17: =Q16+1 -> 46298 | R17: =INDEX($B$27:$H$27,WEEKDAY(Q17,2)) -> 0 | S17: =SUM(R$5:R17) -> 10
A18: Sessions per training day (1 session = 2 hrs) | B18: 1 | K18: =K17+1 -> 46299 | L18: =INDEX($B$7:$H$7,WEEKDAY(K18,2)) -> 0 | M18: =SUM(L$5:L18) -> 10 | N18: =N17+1 -> 46299 | O18: =INDEX($B$17:$H$17,WEEKDAY(N18,2)) -> 0 | P18: =SUM(O$5:O18) -> 10 | Q18: =Q17+1 -> 46299 | R18: =INDEX($B$27:$H$27,WEEKDAY(Q18,2)) -> 0 | S18: =SUM(R$5:R18) -> 10
A19: Total sessions | B19: =COUNT('Tier 2 Creators'!$A$5:$A$16) -> 12 | K19: =K18+1 -> 46300 | L19: =INDEX($B$7:$H$7,WEEKDAY(K19,2)) -> 1 | M19: =SUM(L$5:L19) -> 11 | N19: =N18+1 -> 46300 | O19: =INDEX($B$17:$H$17,WEEKDAY(N19,2)) -> 1 | P19: =SUM(O$5:O19) -> 11 | Q19: =Q18+1 -> 46300 | R19: =INDEX($B$27:$H$27,WEEKDAY(Q19,2)) -> 1 | S19: =SUM(R$5:R19) -> 11
A20: Training days needed | B20: =IFERROR(ROUNDUP(B19/$B$18,0),"") -> 12 | K20: =K19+1 -> 46301 | L20: =INDEX($B$7:$H$7,WEEKDAY(K20,2)) -> 1 | M20: =SUM(L$5:L20) -> 12 | N20: =N19+1 -> 46301 | O20: =INDEX($B$17:$H$17,WEEKDAY(N20,2)) -> 1 | P20: =SUM(O$5:O20) -> 12 | Q20: =Q19+1 -> 46301 | R20: =INDEX($B$27:$H$27,WEEKDAY(Q20,2)) -> 1 | S20: =SUM(R$5:R20) -> 12
A21: Last session date | B21: =IF(MAX('Tier 2 Creators'!$C$5:$C$16)=0,"",MAX('Tier 2 Creators'!$C$5:$C$16)) -> 46301 | K21: =K20+1 -> 46302 | L21: =INDEX($B$7:$H$7,WEEKDAY(K21,2)) -> 1 | M21: =SUM(L$5:L21) -> 13 | N21: =N20+1 -> 46302 | O21: =INDEX($B$17:$H$17,WEEKDAY(N21,2)) -> 1 | P21: =SUM(O$5:O21) -> 13 | Q21: =Q20+1 -> 46302 | R21: =INDEX($B$27:$H$27,WEEKDAY(Q21,2)) -> 1 | S21: =SUM(R$5:R21) -> 13
K22: =K21+1 -> 46303 | L22: =INDEX($B$7:$H$7,WEEKDAY(K22,2)) -> 1 | M22: =SUM(L$5:L22) -> 14 | N22: =N21+1 -> 46303 | O22: =INDEX($B$17:$H$17,WEEKDAY(N22,2)) -> 1 | P22: =SUM(O$5:O22) -> 14 | Q22: =Q21+1 -> 46303 | R22: =INDEX($B$27:$H$27,WEEKDAY(Q22,2)) -> 1 | S22: =SUM(R$5:R22) -> 14
K23: =K22+1 -> 46304 | L23: =INDEX($B$7:$H$7,WEEKDAY(K23,2)) -> 1 | M23: =SUM(L$5:L23) -> 15 | N23: =N22+1 -> 46304 | O23: =INDEX($B$17:$H$17,WEEKDAY(N23,2)) -> 1 | P23: =SUM(O$5:O23) -> 15 | Q23: =Q22+1 -> 46304 | R23: =INDEX($B$27:$H$27,WEEKDAY(Q23,2)) -> 1 | S23: =SUM(R$5:R23) -> 15
A24: Tier 3: Data & Model Builders | K24: =K23+1 -> 46305 | L24: =INDEX($B$7:$H$7,WEEKDAY(K24,2)) -> 0 | M24: =SUM(L$5:L24) -> 15 | N24: =N23+1 -> 46305 | O24: =INDEX($B$17:$H$17,WEEKDAY(N24,2)) -> 0 | P24: =SUM(O$5:O24) -> 15 | Q24: =Q23+1 -> 46305 | R24: =INDEX($B$27:$H$27,WEEKDAY(Q24,2)) -> 0 | S24: =SUM(R$5:R24) -> 15
A25: Start date | B25: 46286 | C25: <- placeholder, edit | K25: =K24+1 -> 46306 | L25: =INDEX($B$7:$H$7,WEEKDAY(K25,2)) -> 0 | M25: =SUM(L$5:L25) -> 15 | N25: =N24+1 -> 46306 | O25: =INDEX($B$17:$H$17,WEEKDAY(N25,2)) -> 0 | P25: =SUM(O$5:O25) -> 15 | Q25: =Q24+1 -> 46306 | R25: =INDEX($B$27:$H$27,WEEKDAY(Q25,2)) -> 0 | S25: =SUM(R$5:R25) -> 15
A26: Training day | B26: Mon | C26: Tue | D26: Wed | E26: Thu | F26: Fri | G26: Sat | H26: Sun | K26: =K25+1 -> 46307 | L26: =INDEX($B$7:$H$7,WEEKDAY(K26,2)) -> 1 | M26: =SUM(L$5:L26) -> 16 | N26: =N25+1 -> 46307 | O26: =INDEX($B$17:$H$17,WEEKDAY(N26,2)) -> 1 | P26: =SUM(O$5:O26) -> 16 | Q26: =Q25+1 -> 46307 | R26: =INDEX($B$27:$H$27,WEEKDAY(Q26,2)) -> 1 | S26: =SUM(R$5:R26) -> 16
A27: Held on this day? (1 = yes, 0 = no) | B27: 1 | C27: 1 | D27: 1 | E27: 1 | F27: 1 | G27: 0 | H27: 0 | K27: =K26+1 -> 46308 | L27: =INDEX($B$7:$H$7,WEEKDAY(K27,2)) -> 1 | M27: =SUM(L$5:L27) -> 17 | N27: =N26+1 -> 46308 | O27: =INDEX($B$17:$H$17,WEEKDAY(N27,2)) -> 1 | P27: =SUM(O$5:O27) -> 17 | Q27: =Q26+1 -> 46308 | R27: =INDEX($B$27:$H$27,WEEKDAY(Q27,2)) -> 1 | S27: =SUM(R$5:R27) -> 17
A28: Sessions per training day (1 session = 2 hrs) | B28: 1 | K28: =K27+1 -> 46309 | L28: =INDEX($B$7:$H$7,WEEKDAY(K28,2)) -> 1 | M28: =SUM(L$5:L28) -> 18 | N28: =N27+1 -> 46309 | O28: =INDEX($B$17:$H$17,WEEKDAY(N28,2)) -> 1 | P28: =SUM(O$5:O28) -> 18 | Q28: =Q27+1 -> 46309 | R28: =INDEX($B$27:$H$27,WEEKDAY(Q28,2)) -> 1 | S28: =SUM(R$5:R28) -> 18
A29: Total sessions | B29: =COUNT('Tier 3 Builders'!$A$5:$A$34) -> 30 | K29: =K28+1 -> 46310 | L29: =INDEX($B$7:$H$7,WEEKDAY(K29,2)) -> 1 | M29: =SUM(L$5:L29) -> 19 | N29: =N28+1 -> 46310 | O29: =INDEX($B$17:$H$17,WEEKDAY(N29,2)) -> 1 | P29: =SUM(O$5:O29) -> 19 | Q29: =Q28+1 -> 46310 | R29: =INDEX($B$27:$H$27,WEEKDAY(Q29,2)) -> 1 | S29: =SUM(R$5:R29) -> 19
A30: Training days needed | B30: =IFERROR(ROUNDUP(B29/$B$28,0),"") -> 30 | K30: =K29+1 -> 46311 | L30: =INDEX($B$7:$H$7,WEEKDAY(K30,2)) -> 1 | M30: =SUM(L$5:L30) -> 20 | N30: =N29+1 -> 46311 | O30: =INDEX($B$17:$H$17,WEEKDAY(N30,2)) -> 1 | P30: =SUM(O$5:O30) -> 20 | Q30: =Q29+1 -> 46311 | R30: =INDEX($B$27:$H$27,WEEKDAY(Q30,2)) -> 1 | S30: =SUM(R$5:R30) -> 20
A31: Last session date | B31: =IF(MAX('Tier 3 Builders'!$C$5:$C$34)=0,"",MAX('Tier 3 Builders'!$C$5:$C$34)) -> 46325 | K31: =K30+1 -> 46312 | L31: =INDEX($B$7:$H$7,WEEKDAY(K31,2)) -> 0 | M31: =SUM(L$5:L31) -> 20 | N31: =N30+1 -> 46312 | O31: =INDEX($B$17:$H$17,WEEKDAY(N31,2)) -> 0 | P31: =SUM(O$5:O31) -> 20 | Q31: =Q30+1 -> 46312 | R31: =INDEX($B$27:$H$27,WEEKDAY(Q31,2)) -> 0 | S31: =SUM(R$5:R31) -> 20
K32: =K31+1 -> 46313 | L32: =INDEX($B$7:$H$7,WEEKDAY(K32,2)) -> 0 | M32: =SUM(L$5:L32) -> 20 | N32: =N31+1 -> 46313 | O32: =INDEX($B$17:$H$17,WEEKDAY(N32,2)) -> 0 | P32: =SUM(O$5:O32) -> 20 | Q32: =Q31+1 -> 46313 | R32: =INDEX($B$27:$H$27,WEEKDAY(Q32,2)) -> 0 | S32: =SUM(R$5:R32) -> 20
K33: =K32+1 -> 46314 | L33: =INDEX($B$7:$H$7,WEEKDAY(K33,2)) -> 1 | M33: =SUM(L$5:L33) -> 21 | N33: =N32+1 -> 46314 | O33: =INDEX($B$17:$H$17,WEEKDAY(N33,2)) -> 1 | P33: =SUM(O$5:O33) -> 21 | Q33: =Q32+1 -> 46314 | R33: =INDEX($B$27:$H$27,WEEKDAY(Q33,2)) -> 1 | S33: =SUM(R$5:R33) -> 21
K34: =K33+1 -> 46315 | L34: =INDEX($B$7:$H$7,WEEKDAY(K34,2)) -> 1 | M34: =SUM(L$5:L34) -> 22 | N34: =N33+1 -> 46315 | O34: =INDEX($B$17:$H$17,WEEKDAY(N34,2)) -> 1 | P34: =SUM(O$5:O34) -> 22 | Q34: =Q33+1 -> 46315 | R34: =INDEX($B$27:$H$27,WEEKDAY(Q34,2)) -> 1 | S34: =SUM(R$5:R34) -> 22
A35: How to use: set the Start date, mark the weekdays the client can attend with 1 (others 0), and choose sessions per training day. Every session is a 2-hour block. | K35: =K34+1 -> 46316 | L35: =INDEX($B$7:$H$7,WEEKDAY(K35,2)) -> 1 | M35: =SUM(L$5:L35) -> 23 | N35: =N34+1 -> 46316 | O35: =INDEX($B$17:$H$17,WEEKDAY(N35,2)) -> 1 | P35: =SUM(O$5:O35) -> 23 | Q35: =Q34+1 -> 46316 | R35: =INDEX($B$27:$H$27,WEEKDAY(Q35,2)) -> 1 | S35: =SUM(R$5:R35) -> 23
A36: Weekend-only client: set Sat = 1 and Sun = 1, all other days = 0. With 2 sessions per training day each Saturday and Sunday is a 4-hour day, so Tier 2 (12 sessions) finishes in 3 weekends. | K36: =K35+1 -> 46317 | L36: =INDEX($B$7:$H$7,WEEKDAY(K36,2)) -> 1 | M36: =SUM(L$5:L36) -> 24 | N36: =N35+1 -> 46317 | O36: =INDEX($B$17:$H$17,WEEKDAY(N36,2)) -> 1 | P36: =SUM(O$5:O36) -> 24 | Q36: =Q35+1 -> 46317 | R36: =INDEX($B$27:$H$27,WEEKDAY(Q36,2)) -> 1 | S36: =SUM(R$5:R36) -> 24
A37: Any other pattern works the same way (for example Tue/Thu evenings with 1 session per day). Defaults are Mon-Fri with 1 session per day, only as a starting point. | K37: =K36+1 -> 46318 | L37: =INDEX($B$7:$H$7,WEEKDAY(K37,2)) -> 1 | M37: =SUM(L$5:L37) -> 25 | N37: =N36+1 -> 46318 | O37: =INDEX($B$17:$H$17,WEEKDAY(N37,2)) -> 1 | P37: =SUM(O$5:O37) -> 25 | Q37: =Q36+1 -> 46318 | R37: =INDEX($B$27:$H$27,WEEKDAY(Q37,2)) -> 1 | S37: =SUM(R$5:R37) -> 25
A38: Helper calendar columns K:S are hidden and drive the dates. Public holidays are not excluded; shift the dates on the tier sheet manually if needed. | K38: =K37+1 -> 46319 | L38: =INDEX($B$7:$H$7,WEEKDAY(K38,2)) -> 0 | M38: =SUM(L$5:L38) -> 25 | N38: =N37+1 -> 46319 | O38: =INDEX($B$17:$H$17,WEEKDAY(N38,2)) -> 0 | P38: =SUM(O$5:O38) -> 25 | Q38: =Q37+1 -> 46319 | R38: =INDEX($B$27:$H$27,WEEKDAY(Q38,2)) -> 0 | S38: =SUM(R$5:R38) -> 25
K39: =K38+1 -> 46320 | L39: =INDEX($B$7:$H$7,WEEKDAY(K39,2)) -> 0 | M39: =SUM(L$5:L39) -> 25 | N39: =N38+1 -> 46320 | O39: =INDEX($B$17:$H$17,WEEKDAY(N39,2)) -> 0 | P39: =SUM(O$5:O39) -> 25 | Q39: =Q38+1 -> 46320 | R39: =INDEX($B$27:$H$27,WEEKDAY(Q39,2)) -> 0 | S39: =SUM(R$5:R39) -> 25
K40: =K39+1 -> 46321 | L40: =INDEX($B$7:$H$7,WEEKDAY(K40,2)) -> 1 | M40: =SUM(L$5:L40) -> 26 | N40: =N39+1 -> 46321 | O40: =INDEX($B$17:$H$17,WEEKDAY(N40,2)) -> 1 | P40: =SUM(O$5:O40) -> 26 | Q40: =Q39+1 -> 46321 | R40: =INDEX($B$27:$H$27,WEEKDAY(Q40,2)) -> 1 | S40: =SUM(R$5:R40) -> 26
...

Sheet Tier 1 Consumers
A1: Tier 1: Report Consumers: 4 sessions x 2 hours
A2: Audience: Managers, executives and business users who read and act on dashboards. Yellow columns are yours to edit; dates come from the Schedule Planner sheet.
A4: Session | B4: Training Day # | C4: Date | D4: Day | E4: Module | F4: Topic | G4: Key Concepts | H4: Hands-on Lab | I4: Planned Hrs | J4: Status | K4: Actual Hrs | L4: Notes / Mistakes Log
A5: 1 | B5: =IFERROR(ROUNDUP(A5/'Schedule Planner'!$B$8,0),"") -> 1 | C5: =IFERROR(INDEX('Schedule Planner'!$K$5:$K$504,MATCH(B5,'Schedule Planner'!$M$5:$M$504,0)),"Set training days") -> 46286 | D5: =IF(ISNUMBER(C5),C5,"") -> 46286 | E5: 1. Power BI Foundations | F5: Power BI orientation & navigation | G5: What Power BI is; Desktop vs Service vs Mobile (what consumers actually use); workspaces, apps, reports vs dashboards; Home, Browse, Favourites, Recent; checking data freshness (last refresh) | H5: Sign in, find and favourite three reports, open an app, locate the last refresh time | I5: 2 | J5: Not Started
A6: 2 | B6: =IFERROR(ROUNDUP(A6/'Schedule Planner'!$B$8,0),"") -> 2 | C6: =IFERROR(INDEX('Schedule Planner'!$K$5:$K$504,MATCH(B6,'Schedule Planner'!$M$5:$M$504,0)),"Set training days") -> 46287 | D6: =IF(ISNUMBER(C6),C6,"") -> 46287 | E6: 2. Explore & Interact with Reports | F6: Reading visuals correctly | G6: Best-fit visual by data relationship: clustered bar/column (comparison), line (trend over time), stacked bar or treemap (part-to-whole), scatter (correlation), waterfall (variance/bridge), sorted bar (ranking), card/KPI (single value), table/matrix (detail), filled or bubble map (geography); reading axes, legends and totals; common misreads (truncated axes, dual axes, overloaded pies) | H6: Interpret a supplied sales dashboard and answer 10 business questions | I6: 2 | J6: Not Started
A7: 3 | B7: =IFERROR(ROUNDUP(A7/'Schedule Planner'!$B$8,0),"") -> 3 | C7: =IFERROR(INDEX('Schedule Planner'!$K$5:$K$504,MATCH(B7,'Schedule Planner'!$M$5:$M$504,0)),"Set training days") -> 46288 | D7: =IF(ISNUMBER(C7),C7,"") -> 46288 | E7: 2. Explore & Interact with Reports | F7: Interacting with reports | G7: Slicers and the filters pane; cross-filtering and highlighting; drill-down and drillthrough; bookmarks and tooltips; Personalise visuals; See data / Show as table; Q&A and Copilot (if licensed) | H7: Answer business questions from a live report using interaction only | I7: 2 | J7: Not Started
A8: 4 | B8: =IFERROR(ROUNDUP(A8/'Schedule Planner'!$B$8,0),"") -> 4 | C8: =IFERROR(INDEX('Schedule Planner'!$K$5:$K$504,MATCH(B8,'Schedule Planner'!$M$5:$M$504,0)),"Set training days") -> 46289 | D8: =IF(ISNUMBER(C8),C8,"") -> 46289 | E8: 3. Share & Stay Informed | F8: Sharing, alerts & data handling | G8: Export to Excel / PDF / PowerPoint and its limits; Analyze in Excel; subscriptions and alerts; mobile app; sharing and permission awareness; sensitivity labels and responsible data use; raising a data issue; end-of-course knowledge check | H8: Set up a subscription and an alert, export a filtered view, complete the knowledge check | I8: 2 | J8: Not Started
A9: Total | I9: =SUM(I5:I8) -> 8 | J9: =COUNTIF(J5:J8,"Completed")&" / "&COUNTA(J5:J8) -> 0 / 4 | K9: =SUM(K5:K8) -> 0

Sheet Tier 2 Creators
A1: Tier 2: Report Creators: 12 sessions x 2 hours
A2: Audience: Business, finance and MIS analysts who build reports from existing or simple datasets. Yellow columns are yours to edit; dates come from the Schedule Planner sheet.
A4: Session | B4: Training Day # | C4: Date | D4: Day | E4: Module | F4: Topic | G4: Key Concepts | H4: Hands-on Lab | I4: Planned Hrs | J4: Status | K4: Actual Hrs | L4: Notes / Mistakes Log
A5: 1 | B5: =IFERROR(ROUNDUP(A5/'Schedule Planner'!$B$18,0),"") -> 1 | C5: =IFERROR(INDEX('Schedule Planner'!$N$5:$N$504,MATCH(B5,'Schedule Planner'!$P$5:$P$504,0)),"Set training days") -> 46286 | D5: =IF(ISNUMBER(C5),C5,"") -> 46286 | E5: 1. Data Connect & Data Preparation | F5: Power BI overview & connecting to data | G5: Desktop-to-Service workflow; Import vs DirectQuery (when each is used); connecting to Excel, CSV, SQL Server and SharePoint; credentials and privacy levels | H5: Install Desktop, connect to three sources and load them | I5: 2 | J5: Not Started
A6: 2 | B6: =IFERROR(ROUNDUP(A6/'Schedule Planner'!$B$18,0),"") -> 2 | C6: =IFERROR(INDEX('Schedule Planner'!$N$5:$N$504,MATCH(B6,'Schedule Planner'!$P$5:$P$504,0)),"Set training days") -> 46287 | D6: =IF(ISNUMBER(C6),C6,"") -> 46287 | E6: 1. Data Connect & Data Preparation | F6: Cleaning data with Power Query | G6: Power Query Editor and applied steps; column profiling; data types; errors and blanks; trim, replace, split, fill down, remove duplicates; filtering rows | H6: Clean a messy sales extract | I6: 2 | J6: Not Started
A7: 3 | B7: =IFERROR(ROUNDUP(A7/'Schedule Planner'!$B$18,0),"") -> 3 | C7: =IFERROR(INDEX('Schedule Planner'!$N$5:$N$504,MATCH(B7,'Schedule Planner'!$P$5:$P$504,0)),"Set training days") -> 46288 | D7: =IF(ISNUMBER(C7),C7,"") -> 46288 | E7: 1. Data Connect & Data Preparation | F7: Shaping & combining data | G7: Merge and append queries; Group By; pivot and unpivot; conditional and custom columns; combining files from a folder | H7: Combine sales, customer and product tables; Module 1 checkpoint quiz | I7: 2 | J7: Not Started
A8: 4 | B8: =IFERROR(ROUNDUP(A8/'Schedule Planner'!$B$18,0),"") -> 4 | C8: =IFERROR(INDEX('Schedule Planner'!$N$5:$N$504,MATCH(B8,'Schedule Planner'!$P$5:$P$504,0)),"Set training days") -> 46289 | D8: =IF(ISNUMBER(C8),C8,"") -> 46289 | E8: 2. Data Model & DAX (Core) | F8: Star schema & relationships | G8: Fact vs dimension tables; cardinality; cross-filter direction; active vs inactive relationships; building and marking a date table | H8: Build a star schema and test the relationships with a matrix | I8: 2 | J8: Not Started
A9: 5 | B9: =IFERROR(ROUNDUP(A9/'Schedule Planner'!$B$18,0),"") -> 5 | C9: =IFERROR(INDEX('Schedule Planner'!$N$5:$N$504,MATCH(B9,'Schedule Planner'!$P$5:$P$504,0)),"Set training days") -> 46290 | D9: =IF(ISNUMBER(C9),C9,"") -> 46290 | E9: 2. Data Model & DAX (Core) | F9: Model tidy-up & DAX fundamentals | G9: Hide fields, formats, hierarchies, sort by column; calculated columns vs measures; SUM, AVERAGE, COUNT, DISTINCTCOUNT, DIVIDE | H9: Write 8 core measures and organise them in a measures table | I9: 2 | J9: Not Started
A10: 6 | B10: =IFERROR(ROUNDUP(A10/'Schedule Planner'!$B$18,0),"") -> 6 | C10: =IFERROR(INDEX('Schedule Planner'!$N$5:$N$504,MATCH(B10,'Schedule Planner'!$P$5:$P$504,0)),"Set training days") -> 46293 | D10: =IF(ISNUMBER(C10),C10,"") -> 46293 | E10: 2. Data Model & DAX (Core) | F10: CALCULATE & filter context | G10: Row vs filter context (intro); CALCULATE; FILTER; ALL and REMOVEFILTERS; percent of total; variables (VAR / RETURN) | H10: Percent of total, filtered totals and a ranking measure | I10: 2 | J10: Not Started
A11: 7 | B11: =IFERROR(ROUNDUP(A11/'Schedule Planner'!$B$18,0),"") -> 7 | C11: =IFERROR(INDEX('Schedule Planner'!$N$5:$N$504,MATCH(B11,'Schedule Planner'!$P$5:$P$504,0)),"Set training days") -> 46294 | D11: =IF(ISNUMBER(C11),C11,"") -> 46294 | E11: 2. Data Model & DAX (Core) | F11: Time intelligence basics | G11: Date table requirements; TOTALYTD, SAMEPERIODLASTYEAR, DATEADD; month-on-month and year-on-year change | H11: Build YoY, MTD and YTD measures; Module 2 checkpoint quiz | I11: 2 | J11: Not Started
A12: 8 | B12: =IFERROR(ROUNDUP(A12/'Schedule Planner'!$B$18,0),"") -> 8 | C12: =IFERROR(INDEX('Schedule Planner'!$N$5:$N$504,MATCH(B12,'Schedule Planner'!$P$5:$P$504,0)),"Set training days") -> 46295 | D12: =IF(ISNUMBER(C12),C12,"") -> 46295 | E12: 3. Visualisations | F12: Choosing the right visual | G12: Best-fit visual by data relationship: clustered bar/column (comparison), line (trend over time), stacked bar or treemap (part-to-whole), scatter (correlation), waterfall (variance/bridge), sorted bar (ranking), card/KPI (single value), table/matrix (detail), filled or bubble map (geography) | H12: Build one visual for each relationship type | I12: 2 | J12: Not Started
A13: 9 | B13: =IFERROR(ROUNDUP(A13/'Schedule Planner'!$B$18,0),"") -> 9 | C13: =IFERROR(INDEX('Schedule Planner'!$N$5:$N$504,MATCH(B13,'Schedule Planner'!$P$5:$P$504,0)),"Set training days") -> 46296 | D13: =IF(ISNUMBER(C13),C13,"") -> 46296 | E13: 3. Visualisations | F13: Report design & accessibility | G13: Page layout, themes and alignment; titles and labels; colour contrast; alt text and tab order; mobile layout | H13: Design a three-page report using a custom theme | I13: 2 | J13: Not Started
A14: 10 | B14: =IFERROR(ROUNDUP(A14/'Schedule Planner'!$B$18,0),"") -> 10 | C14: =IFERROR(INDEX('Schedule Planner'!$N$5:$N$504,MATCH(B14,'Schedule Planner'!$P$5:$P$504,0)),"Set training days") -> 46297 | D14: =IF(ISNUMBER(C14),C14,"") -> 46297 | E14: 3. Visualisations | F14: Interactivity & navigation | G14: Slicers and synced slicers; filters pane; edit interactions; drill-down and drillthrough; bookmarks and buttons; tooltip pages | H14: Build a navigation menu with a drillthrough page | I14: 2 | J14: Not Started
A15: 11 | B15: =IFERROR(ROUNDUP(A15/'Schedule Planner'!$B$18,0),"") -> 11 | C15: =IFERROR(INDEX('Schedule Planner'!$N$5:$N$504,MATCH(B15,'Schedule Planner'!$P$5:$P$504,0)),"Set training days") -> 46300 | D15: =IF(ISNUMBER(C15),C15,"") -> 46300 | E15: 3. Visualisations | F15: Analytics, conditional formatting & AI visuals | G15: Conditional formatting; reference lines; Top N; forecasting; key influencers; decomposition tree; smart narrative | H15: Highlight outliers and explain a KPI change with an AI visual; Module 3 checkpoint quiz | I15: 2 | J15: Not Started
A16: 12 | B16: =IFERROR(ROUNDUP(A16/'Schedule Planner'!$B$18,0),"") -> 12 | C16: =IFERROR(INDEX('Schedule Planner'!$N$5:$N$504,MATCH(B16,'Schedule Planner'!$P$5:$P$504,0)),"Set training days") -> 46301 | D16: =IF(ISNUMBER(C16),C16,"") -> 46301 | E16: 4. Maintenance & Security (Essentials) | F16: Publish, share & capstone | G16: Publishing to the Service; workspaces and roles; apps; scheduled refresh basics; awareness of row-level security and sensitivity labels | H16: Publish a capstone report built on company data and present it for review (rubric scored) | I16: 2 | J16: Not Started
A17: Total | I17: =SUM(I5:I16) -> 24 | J17: =COUNTIF(J5:J16,"Completed")&" / "&COUNTA(J5:J16) -> 0 / 12 | K17: =SUM(K5:K16) -> 0

Sheet Tier 3 Builders
A1: Tier 3: Data & Model Builders: 30 sessions x 2 hours
A2: Audience: BI developers and reporting analysts who own and maintain datasets (PL-300 equivalent). Yellow columns are yours to edit; dates come from the Schedule Planner sheet.
A4: Session | B4: Training Day # | C4: Date | D4: Day | E4: Module | F4: Topic | G4: Key Concepts | H4: Hands-on Lab | I4: Planned Hrs | J4: Status | K4: Actual Hrs | L4: Notes / Mistakes Log
A5: 1 | B5: =IFERROR(ROUNDUP(A5/'Schedule Planner'!$B$28,0),"") -> 1 | C5: =IFERROR(INDEX('Schedule Planner'!$Q$5:$Q$504,MATCH(B5,'Schedule Planner'!$S$5:$S$504,0)),"Set training days") -> 46286 | D5: =IF(ISNUMBER(C5),C5,"") -> 46286 | E5: 1. Data Connect & Data Preparation | F5: Power BI ecosystem & connectivity modes | G5: Desktop, Service and Mobile; report lifecycle; Import vs DirectQuery vs Dual vs Live Connection and when to use each | H5: Install Desktop, tour the interface, connect to a first Excel file | I5: 2 | J5: Not Started
A6: 2 | B6: =IFERROR(ROUNDUP(A6/'Schedule Planner'!$B$28,0),"") -> 2 | C6: =IFERROR(INDEX('Schedule Planner'!$Q$5:$Q$504,MATCH(B6,'Schedule Planner'!$S$5:$S$504,0)),"Set training days") -> 46287 | D6: =IF(ISNUMBER(C6),C6,"") -> 46287 | E6: 1. Data Connect & Data Preparation | F6: Connecting to data sources | G6: Excel, CSV, SQL Server, SharePoint, web and folder sources; credentials, privacy levels, data source settings | H6: Load data from three different source types | I6: 2 | J6: Not Started
A7: 3 | B7: =IFERROR(ROUNDUP(A7/'Schedule Planner'!$B$28,0),"") -> 3 | C7: =IFERROR(INDEX('Schedule Planner'!$Q$5:$Q$504,MATCH(B7,'Schedule Planner'!$S$5:$S$504,0)),"Set training days") -> 46288 | D7: =IF(ISNUMBER(C7),C7,"") -> 46288 | E7: 1. Data Connect & Data Preparation | F7: Power Query basics & data profiling | G7: Power Query Editor, applied steps, column quality / distribution / profile, data types, errors and empty values | H7: Clean a messy file: trim, replace, split, fill down, remove duplicates | I7: 2 | J7: Not Started
A8: 4 | B8: =IFERROR(ROUNDUP(A8/'Schedule Planner'!$B$28,0),"") -> 4 | C8: =IFERROR(INDEX('Schedule Planner'!$Q$5:$Q$504,MATCH(B8,'Schedule Planner'!$S$5:$S$504,0)),"Set training days") -> 46289 | D8: =IF(ISNUMBER(C8),C8,"") -> 46289 | E8: 1. Data Connect & Data Preparation | F8: Shaping & combining data | G8: Pivot, unpivot, transpose; merge queries (all join types); append; Group By; conditional and custom columns | H8: Combine sales, customer and product tables | I8: 2 | J8: Not Started
A9: 5 | B9: =IFERROR(ROUNDUP(A9/'Schedule Planner'!$B$28,0),"") -> 5 | C9: =IFERROR(INDEX('Schedule Planner'!$Q$5:$Q$504,MATCH(B9,'Schedule Planner'!$S$5:$S$504,0)),"Set training days") -> 46290 | D9: =IF(ISNUMBER(C9),C9,"") -> 46290 | E9: 1. Data Connect & Data Preparation | F9: Advanced Power Query | G9: M language basics, parameters, custom functions; reference vs duplicate queries; combine files from a folder; query folding; staging queries | H9: Build a folder-based monthly file ingestion | I9: 2 | J9: Not Started
A10: 6 | B10: =IFERROR(ROUNDUP(A10/'Schedule Planner'!$B$28,0),"") -> 6 | C10: =IFERROR(INDEX('Schedule Planner'!$Q$5:$Q$504,MATCH(B10,'Schedule Planner'!$S$5:$S$504,0)),"Set training days") -> 46293 | D10: =IF(ISNUMBER(C10),C10,"") -> 46293 | E10: 1. Data Connect & Data Preparation | F10: Preparing data for the model | G10: Shaping fact and dimension tables; building a date table; fixing import errors and load performance; dataflows and incremental refresh concepts | H10: Create a clean star-schema-ready dataset | I10: 2 | J10: Not Started
A11: 7 | B11: =IFERROR(ROUNDUP(A11/'Schedule Planner'!$B$28,0),"") -> 7 | C11: =IFERROR(INDEX('Schedule Planner'!$Q$5:$Q$504,MATCH(B11,'Schedule Planner'!$S$5:$S$504,0)),"Set training days") -> 46294 | D11: =IF(ISNUMBER(C11),C11,"") -> 46294 | E11: 1. Data Connect & Data Preparation | F11: Module 1 checkpoint | G11: Review of the whole domain; 20-question quiz; fix gaps | H11: End-to-end: raw files to a fully prepared dataset | I11: 2 | J11: Not Started
A12: 8 | B12: =IFERROR(ROUNDUP(A12/'Schedule Planner'!$B$28,0),"") -> 8 | C12: =IFERROR(INDEX('Schedule Planner'!$Q$5:$Q$504,MATCH(B12,'Schedule Planner'!$S$5:$S$504,0)),"Set training days") -> 46295 | D12: =IF(ISNUMBER(C12),C12,"") -> 46295 | E12: 2. Data Model & DAX | F12: Star schema & model design | G12: Fact vs dimension tables, granularity, normalisation vs denormalisation, Model view and table properties | H12: Build a star schema from the Module 1 data | I12: 2 | J12: Not Started
A13: 9 | B13: =IFERROR(ROUNDUP(A13/'Schedule Planner'!$B$28,0),"") -> 9 | C13: =IFERROR(INDEX('Schedule Planner'!$Q$5:$Q$504,MATCH(B13,'Schedule Planner'!$S$5:$S$504,0)),"Set training days") -> 46296 | D13: =IF(ISNUMBER(C13),C13,"") -> 46296 | E13: 2. Data Model & DAX | F13: Relationships | G13: Cardinality, cross-filter direction, active vs inactive relationships, many-to-many, role-playing dimensions | H13: Create and troubleshoot relationships, including a role-playing date table | I13: 2 | J13: Not Started
A14: 10 | B14: =IFERROR(ROUNDUP(A14/'Schedule Planner'!$B$28,0),"") -> 10 | C14: =IFERROR(INDEX('Schedule Planner'!$Q$5:$Q$504,MATCH(B14,'Schedule Planner'!$S$5:$S$504,0)),"Set training days") -> 46297 | D14: =IF(ISNUMBER(C14),C14,"") -> 46297 | E14: 2. Data Model & DAX | F14: Model properties & usability | G14: Hide fields, sort by column, data categories, formatting, hierarchies, display folders | H14: Tidy the model as if handing it to a business user | I14: 2 | J14: Not Started
A15: 11 | B15: =IFERROR(ROUNDUP(A15/'Schedule Planner'!$B$28,0),"") -> 11 | C15: =IFERROR(INDEX('Schedule Planner'!$Q$5:$Q$504,MATCH(B15,'Schedule Planner'!$S$5:$S$504,0)),"Set training days") -> 46300 | D15: =IF(ISNUMBER(C15),C15,"") -> 46300 | E15: 2. Data Model & DAX | F15: DAX fundamentals | G15: Calculated columns vs measures vs tables; implicit vs explicit measures; row context vs filter context | H15: Write 10 basic measures (SUM, AVERAGE, COUNT, DIVIDE) | I15: 2 | J15: Not Started
A16: 12 | B16: =IFERROR(ROUNDUP(A16/'Schedule Planner'!$B$28,0),"") -> 12 | C16: =IFERROR(INDEX('Schedule Planner'!$Q$5:$Q$504,MATCH(B16,'Schedule Planner'!$S$5:$S$504,0)),"Set training days") -> 46301 | D16: =IF(ISNUMBER(C16),C16,"") -> 46301 | E16: 2. Data Model & DAX | F16: CALCULATE & filter functions | G16: CALCULATE, FILTER, ALL, ALLEXCEPT, REMOVEFILTERS, VALUES, KEEPFILTERS | H16: Percent of total, filtered totals, year-to-date comparisons | I16: 2 | J16: Not Started
... A34: 30 | B34: =IFERROR(ROUNDUP(A34/'Schedule Planner'!$B$28,0),"") -> 30 | C34: =IFERROR(INDEX('Schedule Planner'!$Q$5:$Q$504,MATCH(B34,'Schedule Planner'!$S$5:$S$504,0)),"Set training days") -> 46325 | D34: =IF(ISNUMBER(C34),C34,"") -> 46325 | E34: 5. Mock Exams & Revision | F34: Full mock exam 2 & exam strategy | G34: Second timed mock; time management and flagging questions; final review of notes | H34: Timed mock and final notes review | I34: 2 | J34: Not Started
A35: Total | I35: =SUM(I5:I34) -> 60 | J35: =COUNTIF(J5:J34,"Completed")&" / "&COUNTA(J5:J34) -> 0 / 30 | K35: =SUM(K5:K34) -> 0

Sheet Assessment Log
A1: Assessment Log
A2: Enter Date and Score. % and status calculate automatically. Max Score values are suggested defaults; edit them to match your actual quizzes. The grey italic row is an example only.
A3: Target % | B3: 0.7 | C3: Rough working target (assumption). PL-300 is scored out of 1000 with 700 to pass, so this is not an exact conversion.
A5: Tier | B5: Checkpoint | C5: Session # | D5: Date | E5: Score | F5: Max Score | G5: % Score | H5: Status vs Target | I5: Weak Areas / Notes
A6: Example | B6: Example: Tier 2 Module 1 quiz (ignore or delete) | C6: 3 | D6: 46296 | E6: 8 | F6: 10 | G6: =IF(OR(E6="",F6="",F6=0),"",E6/F6) -> 0.8 | H6: =IF(G6="","",IF(G6>=$B$3,"On track","Revisit")) -> On track | I6: Merge join types
A7: Tier 1 | B7: End-of-course knowledge check | C7: 4 | F7: 10 | G7: =IF(OR(E7="",F7="",F7=0),"",E7/F7) | H7: =IF(G7="","",IF(G7>=$B$3,"On track","Revisit"))
A8: Tier 2 | B8: Module 1 checkpoint quiz: data preparation | C8: 3 | F8: 10 | G8: =IF(OR(E8="",F8="",F8=0),"",E8/F8) | H8: =IF(G8="","",IF(G8>=$B$3,"On track","Revisit"))
A9: Tier 2 | B9: Module 2 checkpoint quiz: model and DAX | C9: 7 | F9: 15 | G9: =IF(OR(E9="",F9="",F9=0),"",E9/F9) | H9: =IF(G9="","",IF(G9>=$B$3,"On track","Revisit"))
A10: Tier 2 | B10: Module 3 checkpoint quiz: visualisations | C10: 11 | F10: 15 | G10: =IF(OR(E10="",F10="",F10=0),"",E10/F10) | H10: =IF(G10="","",IF(G10>=$B$3,"On track","Revisit"))
A11: Tier 2 | B11: Capstone report review (rubric score) | C11: 12 | F11: 20 | G11: =IF(OR(E11="",F11="",F11=0),"",E11/F11) | H11: =IF(G11="","",IF(G11>=$B$3,"On track","Revisit"))
A12: Tier 3 | B12: Module 1 quiz: Data Connect & Preparation | C12: 7 | F12: 20 | G12: =IF(OR(E12="",F12="",F12=0),"",E12/F12) | H12: =IF(G12="","",IF(G12>=$B$3,"On track","Revisit"))
A13: Tier 3 | B13: Module 2 quiz: Data Model & DAX | C13: 16 | F13: 25 | G13: =IF(OR(E13="",F13="",F13=0),"",E13/F13) | H13: =IF(G13="","",IF(G13>=$B$3,"On track","Revisit"))
A14: Tier 3 | B14: Module 3 quiz: Visualisations | C14: 23 | F14: 20 | G14: =IF(OR(E14="",F14="",F14=0),"",E14/F14) | H14: =IF(G14="","",IF(G14>=$B$3,"On track","Revisit"))
A15: Tier 3 | B15: Module 4 quiz: Maintenance & Security | C15: 27 | F15: 20 | G15: =IF(OR(E15="",F15="",F15=0),"",E15/F15) | H15: =IF(G15="","",IF(G15>=$B$3,"On track","Revisit"))
A16: Tier 3 | B16: Full mock exam 1 (optional) | C16: 28 | G16: =IF(OR(E16="",F16="",F16=0),"",E16/F16) | H16: =IF(G16="","",IF(G16>=$B$3,"On track","Revisit"))
A17: Tier 3 | B17: Full mock exam 2 (optional) | C17: 30 | G17: =IF(OR(E17="",F17="",F17=0),"",E17/F17) | H17: =IF(G17="","",IF(G17>=$B$3,"On track","Revisit"))
